<?xml version="1.0" encoding="utf-8"?>
<!-- This URDF was automatically created by SolidWorks to URDF Exporter! Originally created by Stephen Brawner (brawner@gmail.com) 
     Commit Version: 1.6.0-4-g7f85cfe  Build Version: 1.6.7995.38578
     For more information, please see http://wiki.ros.org/sw_urdf_exporter -->
<robot
  name="mobile_robot_v2">
  <link 
    name = "footprint">
  </link>
  
    <joint
      name = "fixed"
      type = "fixed">
      <origin
        xyz="0 0 0.04"
        rpy="0 0 0"/>
      <parent link = "footprint"/>
      <child link= "base_link"/>
    </joint>
  <link
    name="base_link">
    <inertial>
      <origin
        xyz="-0.00818472936933741 -0.000678590625686551 0.031438401008672"
        rpy="0 0 0" />
      <mass
        value="0.576525103470766" />
      <inertia
        ixx="0.00525180212282447"
        ixy="8.53434165530126E-07"
        ixz="-9.34427518096429E-05"
        iyy="0.00662229644460686"
        iyz="8.16586652881834E-06"
        izz="0.0114069490761203" />
    </inertial>
    <visual>
      <origin
        xyz="0 0 0"
        rpy="0 0 0" />
      <geometry>
        <mesh
          filename="package://mobile_robot_v2/meshes/base_link.STL" />
      </geometry>
      <material
        name="">
        <color
          rgba="0.0392156862745098 0.0392156862745098 0.0392156862745098 1" />
      </material>
    </visual>
    <collision>
      <origin
        xyz="0 0 0"
        rpy="0 0 0" />
      <geometry>
        <mesh
          filename="package://mobile_robot_v2/meshes/base_link.STL" />
      </geometry>
    </collision>
  </link>
  <link
    name="front_caster_rotation">
    <inertial>
      <origin
        xyz="0.00275087002781431 -3.8048436632486E-05 -0.0106896661075171"
        rpy="0 0 0" />
      <mass
        value="0.00163932270153928" />
      <inertia
        ixx="1.68947110560921E-07"
        ixy="-2.13476212434035E-10"
        ixz="3.49756773423158E-08"
        iyy="1.53524240702112E-07"
        iyz="-4.8368026925958E-10"
        izz="1.81640673602264E-07" />
    </inertial>
    <visual>
      <origin
        xyz="0 0 0"
        rpy="0 0 0" />
      <geometry>
        <mesh
          filename="package://mobile_robot_v2/meshes/front_caster_rotation.STL" />
      </geometry>
      <material
        name="">
        <color
          rgba="0.686274509803922 0.686274509803922 0.686274509803922 1" />
      </material>
    </visual>
    <collision>
      <origin
        xyz="0 0 0"
        rpy="0 0 0" />
      <geometry>
        <mesh
          filename="package://mobile_robot_v2/meshes/front_caster_rotation.STL" />
      </geometry>
    </collision>
  </link>
  <joint
    name="front_caster_rotation_joint"
    type="continuous">
    <origin
      xyz="0.184 0 -0.0016"
      rpy="0 0 0" />
    <parent
      link="base_link" />
    <child
      link="front_caster_rotation" />
    <axis
      xyz="0 0 1" />
  </joint>
  <link
    name="front_caster_wheel">
    <inertial>
      <origin
        xyz="6.92779167366098E-14 1.0096090630185E-13 -0.00700000000002304"
        rpy="0 0 0" />
      <mass
        value="0.0113625256694897" />
      <inertia
        ixx="9.06331517306513E-07"
        ixy="6.67864439182371E-23"
        ixz="4.0939243183212E-22"
        iyy="9.06331517306513E-07"
        iyz="8.40415502354954E-22"
        izz="1.43202222816787E-06" />
    </inertial>
    <visual>
      <origin
        xyz="0 0 0"
        rpy="0 0 0" />
      <geometry>
        <mesh
          filename="package://mobile_robot_v2/meshes/front_caster_wheel.STL" />
      </geometry>
      <material
        name="">
        <color
          rgba="0.498039215686275 0.498039215686275 0.498039215686275 1" />
      </material>
    </visual>
    <collision>
      <origin
        xyz="0 0 0"
        rpy="0 0 0" />
      <geometry>
        <mesh
          filename="package://mobile_robot_v2/meshes/front_caster_wheel.STL" />
      </geometry>
    </collision>
  </link>
  <joint
    name="front_caster_wheel_joint"
    type="continuous">
    <origin
      xyz="0.010096 -0.006861 -0.0244"
      rpy="1.557 -1.5708 0" />
    <parent
      link="front_caster_rotation" />
    <child
      link="front_caster_wheel" />
    <axis
      xyz="0 0 1" />
  </joint>
  <link
    name="rp_lidar">
    <inertial>
      <origin
        xyz="-0.00676806015122415 9.18826098207717E-05 -0.0219029751317191"
        rpy="0 0 0" />
      <mass
        value="0.170369096773262" />
      <inertia
        ixx="7.85144528233466E-05"
        ixy="-1.02594699797501E-07"
        ixz="-2.02793883969737E-05"
        iyy="0.000122718368622727"
        iyz="3.97473689157691E-07"
        izz="0.000140428163899051" />
    </inertial>
    <visual>
      <origin
        xyz="0 0 0"
        rpy="0 0 0" />
      <geometry>
        <mesh
          filename="package://mobile_robot_v2/meshes/sensors/rp_lidar.STL" />
      </geometry>
      <material
        name="">
        <color
          rgba="0.792156862745098 0.819607843137255 0.933333333333333 1" />
      </material>
    </visual>
    <collision>
      <origin
        xyz="0 1111 0"
        rpy="0 1111 0" />
      <geometry>
        <mesh
          filename="package://mobile_robot_v2/meshes/sensors/hokuyo.dae" />
      </geometry>
    </collision>
  </link>
  <joint
    name="rp_lidar_joint"
    type="fixed">
    <origin
      xyz="0.011811 0 0.1522"
      rpy="0 0 0" />
    <parent
      link="base_link" />
    <child
      link="rp_lidar" />
    <axis
      xyz="0 0 0" />
  </joint>
  <link
    name="rear_right_wheel">
    <inertial>
      <origin
        xyz="-1.47104550762833E-15 0.0156021168327709 -1.63757896132211E-15"
        rpy="0 0 0" />
      <mass
        value="0.335246550060458" />
      <inertia
        ixx="0.000556427367899459"
        ixy="-9.22942640635914E-19"
        ixz="-2.69725727134846E-20"
        iyy="0.00106371956621461"
        iyz="-8.72914457924714E-19"
        izz="0.000556427367899459" />
    </inertial>
    <visual>
      <origin
        xyz="0 0 0"
        rpy="0 0 0" />
      <geometry>
        <mesh
          filename="package://mobile_robot_v2/meshes/rear_right_wheel.STL" />
      </geometry>
      <material
        name="">
        <color
          rgba="0.745098039215686 0.745098039215686 0.745098039215686 1" />
      </material>
    </visual>
    <collision>
      <origin
        xyz="0 0 0"
        rpy="0 0 0" />
      <geometry>
        <mesh
          filename="package://mobile_robot_v2/meshes/rear_right_wheel.STL" />
      </geometry>
    </collision>
  </link>
  <joint
    name="rear_right_wheel_joint"
    type="continuous">
    <origin
      xyz="-0.081026 -0.22709 0.0335"
      rpy="0 0 0" />
    <parent
      link="base_link" />
    <child
      link="rear_right_wheel" />
    <axis
      xyz="0 1 0" />
  </joint>
  <link
    name="rear_left_wheel">
    <inertial>
      <origin
        xyz="6.93889390390723E-16 -0.0163978831672308 2.77555756156289E-17"
        rpy="0 0 0" />
      <mass
        value="0.335246550060458" />
      <inertia
        ixx="0.000556427367899459"
        ixy="-9.96062939791216E-19"
        ixz="-1.32872456944108E-20"
        iyy="0.00106371956621461"
        iyz="-8.85952845790982E-19"
        izz="0.000556427367899459" />
    </inertial>
    <visual>
      <origin
        xyz="0 0 0"
        rpy="0 0 0" />
      <geometry>
        <mesh
          filename="package://mobile_robot_v2/meshes/rear_left_wheel.STL" />
      </geometry>
      <material
        name="">
        <color
          rgba="0.745098039215686 0.745098039215686 0.745098039215686 1" />
      </material>
    </visual>
    <collision>
      <origin
        xyz="0 0 0"
        rpy="0 0 0" />
      <geometry>
        <mesh
          filename="package://mobile_robot_v2/meshes/rear_left_wheel.STL" />
      </geometry>
    </collision>
  </link>
  <joint
    name="rear_left_wheel_joint"
    type="continuous">
    <origin
      xyz="-0.081026 0.22731 0.0335"
      rpy="0 0 0" />
    <parent
      link="base_link" />
    <child
      link="rear_left_wheel" />
    <axis
      xyz="0 1 0" />
  </joint>

    <!--diff  driver plugin -->
  <gazebo>
      <plugin name="gazebo_ros_control" filename="libgazebo_ros_control.so">
        <robotNamespace>/</robotNamespace>
        <controlPeriod>0.001</controlPeriod>
        <legacyModeNS>false</legacyModeNS>
      </plugin>
    </gazebo>
  <!--######################################################################-->
  <gazebo>
      <plugin name="diff_drive_controller" filename="libgazebo_ros_diff_drive.so">
        <legacyMode>false</legacyMode>
        <alwaysOn>true</alwaysOn>
        <updateRate>1000.0</updateRate>
        <leftJoint>rear_left_wheel_joint</leftJoint>
        <rightJoint>rear_right_wheel_joint</rightJoint>
        <wheelSeparation>0.4</wheelSeparation>
        <wheelDiameter>0.2</wheelDiameter>
        <wheelTorque>10</wheelTorque>
        <publishTf>1</publishTf>
        <odometryFrame>/odom</odometryFrame>
        <commandTopic>/kbot/i_robotlab/cmd_vel</commandTopic>
        <odometryTopic>/kbot/i_robotlab/odom</odometryTopic>
        <robotBaseFrame>footprint</robotBaseFrame>
        <wheelAcceleration>2.8</wheelAcceleration>
        <publishWheelJointState>true</publishWheelJointState>
        <publishWheelTF>true</publishWheelTF>
        <odometrySource>world</odometrySource>
        <rosDebugLevel>Debug</rosDebugLevel>
      </plugin>
  </gazebo>
  <!--######################################################################-->
  <gazebo reference="rear_left_wheel_joint">
  <mu1 value="1.0"/>
  <mu2 value="1.0"/>
  <kp value="10000000.0" />
  <kd value="1.0" />
  <fdir1 value="1 0 0"/>
  </gazebo>

  <gazebo reference="rear_right_wheel_joint">
  <mu1 value="1.0"/>
  <mu2 value="1.0"/>
  <kp value="10000000.0" />
  <kd value="1.0" />
  <fdir1 value="1 0 0"/>
  </gazebo>
  

  <!--######################################################################-->
  <transmission name="left_wheel_trans" type="SimpleTransmission">
    <type>transmission_interface/SimpleTransmission</type>
    <actuator name="left_wheel_motor">
    <hardwareInterface>hardware_interface/VelocityJointInterface</hardwareInterface>
    <mechanicalReduction>1</mechanicalReduction>
    </actuator>
    <joint name="rear_left_wheel_joint">
    <hardwareInterface>hardware_interface/VelocityJointInterface</hardwareInterface>
    </joint>
  </transmission>

  <transmission name="right_wheel_trans" type="SimpleTransmission">
    <type>transmission_interface/SimpleTransmission</type>
    <actuator name="right_wheel_motor">
    <hardwareInterface>hardware_interface/VelocityJointInterface</hardwareInterface>
    <mechanicalReduction>1</mechanicalReduction>
    </actuator>
    <joint name="rear_right_wheel_joint">
    <hardwareInterface>hardware_interface/VelocityJointInterface</hardwareInterface>
    </joint>
  </transmission>

<!-- hokuyo -->
  <gazebo reference="rp_lidar">
    <sensor type="ray" name="head_hokuyo_sensor">
      <pose>0.01 0 0.03 0 -0 0</pose>
      <visualize>true</visualize>
      <update_rate>10</update_rate>
      <ray>
        <scan>
          <horizontal>
            <samples>640</samples>
            <resolution>1</resolution>
            <min_angle>-3.141592</min_angle>
            <max_angle>3.141592</max_angle>
          </horizontal>
        </scan>
        <range>
          <min>0.1</min>
          <max>12.0</max>
          <resolution>0.01</resolution>
        </range>
        <noise>
          <type>gaussian</type>
          <!--Noise parameters based on published spec for Hokuyo laser
               achieving "+-30mm" accuracy at range < 10m.  A mean of 0.0m and
               stddev of 0.01m will put 99.7% of samples within 0.03m of the true
               reading. --> 
          <mean>0.0</mean>
          <stddev>0.01</stddev>
        </noise>
      </ray>
      <plugin 
      name="gazebo_ros_head_hokuyo_controller" filename="libgazebo_ros_laser.so">
         <always_on>1</always_on>
        <update_rate>30</update_rate>
        <visualize>true</visualize>
        <topicName>/kbot/i_robotlab/scan</topicName>
        <frameName>rp_lidar</frameName>
      </plugin>
    </sensor>
  </gazebo> 
</robot>
